Workbook
Name task_end: 'Atlantic Packaging'!$F1
Name task_end: Template!$F1
Name task_progress: 'Atlantic Packaging'!$D1
Name task_progress: Template!$D1
Name task_start: 'Atlantic Packaging'!$E1
Name task_start: Template!$E1
Name today: 'Atlantic Packaging'!$E$3
Name today: Template!$E$3
Name valuevx: 42.314159

Sheet Projects
B1: Projects
B2: Idea Networks - click a project name to open it
B3: =HYPERLINK("#'Instructions'!A1","How to use this workbook ►") -> How to use this workbook ►
B5: Project | C5: Client | D5: Project Manager | E5: Start | F5: Finish | G5: Progress | H5: Status | I5: Archived | J5: Tab | K5: Client Email
B6: =HYPERLINK("#'"&SUBSTITUTE(J6,"'","''")&"'!A1",'Atlantic Packaging'!$B$1) -> Atlantic Packaging Network Install | C6: Atlantic Packaging | D6: ='Atlantic Packaging'!$B$3&"" -> Ryan King | E6: =IF(COUNT('Atlantic Packaging'!$E$7:$E$1000)=0,"",MIN('Atlantic Packaging'!$E$7:$E$1000)) -> 45313 | F6: =IF(COUNT('Atlantic Packaging'!$F$7:$F$1000)=0,"",MAX('Atlantic Packaging'!$F$7:$F$1000)) -> 45400 | G6: =IFERROR(SUMPRODUCT('Atlantic Packaging'!$D$7:$D$1000,'Atlantic Packaging'!$H$7:$H$1000)/SUM('Atlantic Packaging'!$H$7:$H$1000),"") -> 7.3619632e-05 | H6: =IF(I6="Yes","Archived",IF(E6="","Not scheduled",IF(N(G6)>=1,"Complete",IF(TODAY()<E6,"Not started",IF(TODAY()>F6,"Overdue","In progress"))))) -> Overdue | J6: Atlantic Packaging

Sheet Instructions
B1: How to use this workbook
B2: One Gantt chart per project, plus a Projects overview. Idea Networks.
C3: =HYPERLINK("#'Projects'!A1","◄ All projects") -> ◄ All projects
B4: Finding your way around
B5: • | C5: Projects tab: one line per project with client, project manager, start, finish, progress and status. Click a project name to open its tab.
B6: • | C6: One tab per project: the Gantt chart. The '◄ All projects' link at the top of the chart takes you back to the Projects tab.
B7: • | C7: Template (hidden tab): new projects are copied from it. To change what new projects start with, right-click any tab > Unhide > Template, edit it, then hide it again.
B9: Start a new project
C10: 1. Go to the Projects tab and click Run New Project.
C11: 2. Enter the project name and start date (for example 2026-11-02); client and project manager are optional. Click Run.
C12: 3. The new tab opens with one 'Planning' section and one task. Rename them and add your own sections and tasks.
B14: Build the schedule
B15: • | C15: Run Add Task: select a task first; the new task goes right below it. Select a section header instead and it goes at the end of that section.
B16: • | C16: Run Add Section: select anything in a section; the new section goes after it.
B17: • | C17: To delete tasks, select their rows, right-click > Delete. Delete a section the same way (its header row plus its tasks).
B18: • | C18: Type task names, Assigned To, Progress (%), Start and End straight into the cells. The bars, DAYS and the Projects tab update by themselves.
B19: • | C19: Display Week (cell E4) moves the chart: 1 is the week the project starts, 2 the week after, and so on.
B21: Finish or put away a project
B22: • | C22: On the Projects tab, click the project's row, then Run Archive Project. Its tab is hidden and its status shows Archived.
B23: • | C23: To bring it back, click the archived row and Run Archive Project again.
B25: Good to know
B26: • | C26: The buttons run Office Scripts. Each one asks for its inputs in a small panel; click Run to go ahead or Cancel to stop. They are also on the Automate tab of the ribbon.
B27: • | C27: Script actions can't always be undone with Ctrl+Z, so take care with Archive and deleting.
B28: • | C28: Keep all tasks above the grey 'Insert new rows ABOVE this one' row.
B29: • | C29: If you rename a project tab, type the new name in its Tab cell on the Projects tab so the link and Archive keep working.
B30: • | C30: Progress on the Projects tab weights each task by its length in days. Status turns Overdue when today is past the last end date and progress is under 100%.
B31: • | C31: Everyone should work in this one shared file (from the link, in the browser or Teams), not a downloaded copy.

Sheet Atlantic Packaging
B1: Atlantic Packaging Network Install | I1: =HYPERLINK("#'Projects'!A1","◄ All projects") -> ◄ All projects
B2: Idea Networks | D2: Project Start: | E2: 45313
B3: Ryan King | D3: Today: | E3: =TODAY() -> 46317 | AS3: Progress Invoice | BT3: Progress invoice | CO3: Completion Invoice
D4: Display Week: | E4: 1 | I4: =I5 -> 45313 | P4: =P5 -> 45320 | W4: =W5 -> 45327 | AD4: =AD5 -> 45334 | AK4: =AK5 -> 45341 | AR4: =AR5 -> 45348 | AY4: =AY5 -> 45355 | BF4: =BF5 -> 45362 | BM4: =BM5 -> 45369 | BT4: =BT5 -> 45376 | CA4: =CA5 -> 45383 | CH4: =CH5 -> 45390 | CO4: =CO5 -> 45397 | CV4: =CV5 -> 45404 | DC4: =DC5 -> 45411 | DJ4: =DJ5 -> 45418 | DQ4: =DQ5 -> 45425 | DX4: =DX5 -> 45432
I5: =E2-WEEKDAY(E2,1)+2+7*(E4-1) -> 45313 | J5: =I5+1 -> 45314 | K5: =J5+1 -> 45315 | L5: =K5+1 -> 45316 | M5: =L5+1 -> 45317 | N5: =M5+1 -> 45318 | O5: =N5+1 -> 45319 | P5: =O5+1 -> 45320 | Q5: =P5+1 -> 45321 | ... ED5: =EC5+1 -> 45438
B6: TASK | C6: ASSIGNED TO | D6: PROGRESS | E6: START | F6: END | H6: DAYS | I6: =LEFT(TEXT(I5,"ddd"),1) -> M | J6: =LEFT(TEXT(J5,"ddd"),1) -> T | K6: =LEFT(TEXT(K5,"ddd"),1) -> W | L6: =LEFT(TEXT(L5,"ddd"),1) -> T | M6: =LEFT(TEXT(M5,"ddd"),1) -> F | N6: =LEFT(TEXT(N5,"ddd"),1) -> S | O6: =LEFT(TEXT(O5,"ddd"),1) -> S | P6: =LEFT(TEXT(P5,"ddd"),1) -> M | ... ED6: =LEFT(TEXT(ED5,"ddd"),1) -> S
H7: =IF(OR(ISBLANK(task_start),ISBLANK(task_end)),"",task_end-task_start+1)
B8: Pre-Installation Coordination | H8: =IF(OR(ISBLANK(task_start),ISBLANK(task_end)),"",task_end-task_start+1)
B9: Confirm Cabinet Locations & CO Approval | D9: 0 | E9: 45313 | F9: 45324 | H9: =IF(OR(ISBLANK(task_start),ISBLANK(task_end)),"",task_end-task_start+1) -> 12
B10: Order Material (Above Dependency) | D10: 0 | E10: 45313 | F10: 45324 | H10: =IF(OR(ISBLANK(task_start),ISBLANK(task_end)),"",task_end-task_start+1) -> 12
B11: Print Site Drawings (Requested) | D11: 0 | E11: 45313 | F11: 45324 | H11: =IF(OR(ISBLANK(task_start),ISBLANK(task_end)),"",task_end-task_start+1) -> 12
B12: Confirm Lift Availability | D12: 0 | E12: 45313 | F12: 45324 | H12: =IF(OR(ISBLANK(task_start),ISBLANK(task_end)),"",task_end-task_start+1) -> 12
B13: Confirm and Schedule Manpower | D13: 0 | E13: 45313 | F13: 45324 | H13: =IF(OR(ISBLANK(task_start),ISBLANK(task_end)),"",task_end-task_start+1) -> 12
B14: Site Review | D14: 0 | E14: 45316 | F14: 45316 | H14: =IF(OR(ISBLANK(task_start),ISBLANK(task_end)),"",task_end-task_start+1) -> 1
B15: Cabinet Installation | H15: =IF(OR(ISBLANK(task_start),ISBLANK(task_end)),"",task_end-task_start+1)
B16: Planning and Preparation | D16: 0 | E16: 45327 | F16: 45327 | H16: =IF(OR(ISBLANK(task_start),ISBLANK(task_end)),"",task_end-task_start+1) -> 1
B17: Cabinet 1&2 | D17: 0 | E17: 45328 | F17: 45328 | H17: =IF(OR(ISBLANK(task_start),ISBLANK(task_end)),"",task_end-task_start+1) -> 1
B18: Cabinet 3&4 | D18: 0 | E18: 45329 | F18: 45329 | H18: =IF(OR(ISBLANK(task_start),ISBLANK(task_end)),"",task_end-task_start+1) -> 1
B19: Cabinet 5 & MDF Cabinets | D19: 0 | E19: 45330 | F19: 45330 | H19: =IF(OR(ISBLANK(task_start),ISBLANK(task_end)),"",task_end-task_start+1) -> 1
B20: Cable Pathway | D20: 0 | E20: 45327 | F20: 45342 | H20: =IF(OR(ISBLANK(task_start),ISBLANK(task_end)),"",task_end-task_start+1) -> 16
B21: Fiber Installation | H21: =IF(OR(ISBLANK(task_start),ISBLANK(task_end)),"",task_end-task_start+1)
B22: Planning and Preparation | D22: 0 | E22: 45329 | F22: 45329 | H22: =IF(OR(ISBLANK(task_start),ISBLANK(task_end)),"",task_end-task_start+1) -> 1
B23: Rough In | D23: 0.001 | E23: 45330 | F23: 45341 | H23: =IF(OR(ISBLANK(task_start),ISBLANK(task_end)),"",task_end-task_start+1) -> 12
B24: Termination | D24: 0 | E24: 45342 | F24: 45345 | H24: =IF(OR(ISBLANK(task_start),ISBLANK(task_end)),"",task_end-task_start+1) -> 4
B25: Testing | D25: 0 | E25: 45346 | F25: 45348 | H25: =IF(OR(ISBLANK(task_start),ISBLANK(task_end)),"",task_end-task_start+1) -> 3
B26: Clean Up Documentation | D26: 0 | E26: 45349 | F26: 45349 | H26: =IF(OR(ISBLANK(task_start),ISBLANK(task_end)),"",task_end-task_start+1) -> 1
B27: Copper Installation | H27: =IF(OR(ISBLANK(task_start),ISBLANK(task_end)),"",task_end-task_start+1)
B28: Planning and Preparation | D28: 0 | E28: 45341 | F28: 45341 | H28: =IF(OR(ISBLANK(task_start),ISBLANK(task_end)),"",task_end-task_start+1) -> 1
B29: Rough In | D29: 0 | E29: 45342 | F29: 45366 | H29: =IF(OR(ISBLANK(task_start),ISBLANK(task_end)),"",task_end-task_start+1) -> 25
B30: Termination | D30: 0 | E30: 45369 | F30: 45376 | H30: =IF(OR(ISBLANK(task_start),ISBLANK(task_end)),"",task_end-task_start+1) -> 8
B31: Testing | D31: 0 | E31: 45377 | F31: 45386 | H31: =IF(OR(ISBLANK(task_start),ISBLANK(task_end)),"",task_end-task_start+1) -> 10
B32: Clean Up Documentation | D32: 0 | E32: 45387 | F32: 45387 | H32: =IF(OR(ISBLANK(task_start),ISBLANK(task_end)),"",task_end-task_start+1) -> 1
B33: Equipment Installation | H33: =IF(OR(ISBLANK(task_start),ISBLANK(task_end)),"",task_end-task_start+1)
B34: AP Deployment/Documentation | D34: 0 | E34: 45378 | F34: 45379 | H34: =IF(OR(ISBLANK(task_start),ISBLANK(task_end)),"",task_end-task_start+1) -> 2
B35: IT Cabinet Equipment | D35: 0 | E35: 45380 | F35: 45381 | H35: =IF(OR(ISBLANK(task_start),ISBLANK(task_end)),"",task_end-task_start+1) -> 2
B36: Clean and Remove Site tools | D36: 0 | E36: 45390 | F36: 45390 | H36: =IF(OR(ISBLANK(task_start),ISBLANK(task_end)),"",task_end-task_start+1) -> 1
B37: Documentation | D37: 0 | E37: 45391 | F37: 45394 | H37: =IF(OR(ISBLANK(task_start),ISBLANK(task_end)),"",task_end-task_start+1) -> 4
B38: Manufacturer Certification | D38: 0 | E38: 45394 | F38: 45400 | H38: =IF(OR(ISBLANK(task_start),ISBLANK(task_end)),"",task_end-task_start+1) -> 7
H39: =IF(OR(ISBLANK(task_start),ISBLANK(task_end)),"",task_end-task_start+1)
H40: =IF(OR(ISBLANK(task_start),ISBLANK(task_end)),"",task_end-task_start+1)
...

Sheet Template
B1: New Project | I1: =HYPERLINK("#'Projects'!A1","◄ All projects") -> ◄ All projects
B2: Idea Networks | D2: Project Start: | E2: 45313
B3: Project Manager | D3: Today: | E3: =TODAY() -> 46317
D4: Display Week: | E4: 1 | I4: =I5 -> 45313 | P4: =P5 -> 45320 | W4: =W5 -> 45327 | AD4: =AD5 -> 45334 | AK4: =AK5 -> 45341 | AR4: =AR5 -> 45348 | AY4: =AY5 -> 45355 | BF4: =BF5 -> 45362 | BM4: =BM5 -> 45369 | BT4: =BT5 -> 45376 | CA4: =CA5 -> 45383 | CH4: =CH5 -> 45390 | CO4: =CO5 -> 45397 | CV4: =CV5 -> 45404 | DC4: =DC5 -> 45411 | DJ4: =DJ5 -> 45418 | DQ4: =DQ5 -> 45425 | DX4: =DX5 -> 45432
I5: =E2-WEEKDAY(E2,1)+2+7*(E4-1) -> 45313 | J5: =I5+1 -> 45314 | K5: =J5+1 -> 45315 | L5: =K5+1 -> 45316 | M5: =L5+1 -> 45317 | N5: =M5+1 -> 45318 | O5: =N5+1 -> 45319 | P5: =O5+1 -> 45320 | Q5: =P5+1 -> 45321 | ... ED5: =EC5+1 -> 45438
B6: TASK | C6: ASSIGNED TO | D6: PROGRESS | E6: START | F6: END | H6: DAYS | I6: =LEFT(TEXT(I5,"ddd"),1) -> M | J6: =LEFT(TEXT(J5,"ddd"),1) -> T | K6: =LEFT(TEXT(K5,"ddd"),1) -> W | L6: =LEFT(TEXT(L5,"ddd"),1) -> T | M6: =LEFT(TEXT(M5,"ddd"),1) -> F | N6: =LEFT(TEXT(N5,"ddd"),1) -> S | O6: =LEFT(TEXT(O5,"ddd"),1) -> S | P6: =LEFT(TEXT(P5,"ddd"),1) -> M | ... ED6: =LEFT(TEXT(ED5,"ddd"),1) -> S
H7: =IF(OR(ISBLANK(task_start),ISBLANK(task_end)),"",task_end-task_start+1)
B8: Planning | H8: =IF(OR(ISBLANK(task_start),ISBLANK(task_end)),"",task_end-task_start+1)
B9: New Task | D9: 0 | E9: 45313 | F9: 45313 | H9: =IF(OR(ISBLANK(task_start),ISBLANK(task_end)),"",task_end-task_start+1) -> 1
H10: =IF(OR(ISBLANK(task_start),ISBLANK(task_end)),"",task_end-task_start+1)
H11: =IF(OR(ISBLANK(task_start),ISBLANK(task_end)),"",task_end-task_start+1)
H12: =IF(OR(ISBLANK(task_start),ISBLANK(task_end)),"",task_end-task_start+1)
B13: Insert new rows ABOVE this one | H13: =IF(OR(ISBLANK(task_start),ISBLANK(task_end)),"",task_end-task_start+1)

Sheet About
B2: SIMPLE GANTT CHART by Vertex42.com
B3: https://www.vertex42.com/ExcelTemplates/simple-gantt-chart.html
B4: © 2018-2019 Vertex42 LLC
B6: About This Template
B7: This template provides a simple way to create a Gantt chart to help visualize and track your project. Simply enter your tasks and start and end dates - no formulas required. The bars in the Gantt chart represent the duration of the task and are displayed using conditional formatting. Insert new tasks by inserting new rows.
B9: Additional Help
B10: Click on the link below to visit vertex42.com and learn more about how to use this template, such as how to calculate days and work days, create task dependencies, change the colors of the bars, add a scroll bar to make it easier to change the display week, extend the date range displayed in the chart, etc.
B11: How to Use the Simple Gantt Chart
B13: =HYPERLINK("https://vertex42.link/HowToMakeAGanttChart","► Watch How This Gantt Chart Was Created") -> ► Watch How This Gantt Chart Was Created
B15: More Project Management Templates
B16: Visit Vertex42.com to download other project management templates, including different types of project schedules, Gantt charts, tasks lists, etc.
B17: Project Management Templates
B19: About Vertex42
B20: Vertex42.com provides over 300 professionally designed spreadsheet templates for business, home, and education - most of which are free to download. Their collection includes a variety of calendars, planners, and schedules as well as personal finance spreadsheets for budgeting, debt reduction, and loan amortization.
B22: Businesses will find invoices, time sheets, inventory trackers, financial statements, and project planning templates. Teachers and students will find resources such as class schedules, grade books, and attendance sheets. Organize your family life with meal planners, checklists, and exercise logs. Each template is thoroughly researched, refined, and improved over time through feedback from thousands of users.
